*** Starting uWSGI 2.0.15 (64bit) on [Tue Jan  9 22:12:50 2018] ***
compiled with version: 4.8.5 20150623 (Red Hat 4.8.5-16) on 09 January 2018 21:39:16
os: Linux-3.10.0-229.el7.x86_64 #1 SMP Fri Mar 6 11:36:42 UTC 2015
nodename: rest-app01
machine: x86_64
clock source: unix
detected number of CPU cores: 2
current working directory: /
detected binary path: /var/www/html/items-rest/venv/bin/uwsgi
!!! no internal routing support, rebuild with pcre support !!!
your processes number limit is 7285
your memory page size is 4096 bytes
 *** WARNING: you have enabled harakiri without post buffering. Slow upload could be rejected on post-unbuffered webservers *** 
detected max file descriptor number: 1024
lock engine: pthread robust mutexes
thunder lock: disabled (you can enable it with --thunder-lock)
uwsgi socket 0 bound to UNIX address /var/www/html/items-rest/socket.sock fd 3
Python version: 3.4.5 (default, Dec 11 2017, 14:22:24)  [GCC 4.8.5 20150623 (Red Hat 4.8.5-16)]
Set PythonHome to /var/www/html/items-rest/venv
Python main interpreter initialized at 0x1334690
python threads support enabled
your server socket listen backlog is limited to 100 connections
your mercy for graceful operations on workers is 60 seconds
mapped 1303488 bytes (1272 KB) for 64 cores
*** Operational MODE: preforking+threaded ***
added /var/www/html/items-rest/ to pythonpath.
WSGI app 0 (mountpoint='') ready in 0 seconds on interpreter 0x1334690 pid: 13286 (default app)
*** uWSGI is running in multiple interpreter mode ***
spawned uWSGI master process (pid: 13286)
spawned uWSGI worker 1 (pid: 13288, cores: 8)
spawned uWSGI worker 2 (pid: 13289, cores: 8)
spawned uWSGI worker 3 (pid: 13290, cores: 8)
spawned uWSGI worker 4 (pid: 13298, cores: 8)
spawned uWSGI worker 5 (pid: 13299, cores: 8)
spawned uWSGI worker 6 (pid: 13300, cores: 8)
spawned uWSGI worker 7 (pid: 13308, cores: 8)
spawned uWSGI worker 8 (pid: 13309, cores: 8)
[pid: 13309|app: 0|req: 1/1] 192.168.2.20 () {44 vars in 610 bytes} [Tue Jan  9 22:29:49 2018] POST /register => generated 42 bytes in 431 msecs (HTTP/1.1 201) 2 headers in 76 bytes (1 switches on core 0)
announcing my loyalty to the Emperor...
kwood
[pid: 13308|app: 0|req: 1/2] 192.168.2.20 () {44 vars in 602 bytes} [Tue Jan  9 22:30:00 2018] POST /auth => generated 193 bytes in 61 msecs (HTTP/1.1 200) 2 headers in 72 bytes (2 switches on core 0)
announcing my loyalty to the Emperor...
[pid: 13298|app: 0|req: 1/3] 192.168.2.20 () {40 vars in 523 bytes} [Tue Jan  9 22:30:13 2018] GET /items => generated 14 bytes in 51 msecs (HTTP/1.1 200) 2 headers in 71 bytes (1 switches on core 0)
announcing my loyalty to the Emperor...
[pid: 13309|app: 0|req: 2/4] 192.168.2.20 () {44 vars in 614 bytes} [Tue Jan  9 22:30:22 2018] POST /item/shirt => generated 52 bytes in 9 msecs (HTTP/1.1 500) 2 headers in 90 bytes (1 switches on core 3)
[pid: 13298|app: 0|req: 2/5] 192.168.2.20 () {44 vars in 614 bytes} [Tue Jan  9 22:31:13 2018] POST /item/shirt => generated 52 bytes in 19 msecs (HTTP/1.1 500) 2 headers in 90 bytes (1 switches on core 7)
[pid: 13298|app: 0|req: 3/6] 192.168.2.20 () {44 vars in 612 bytes} [Tue Jan  9 22:31:32 2018] POST /item/test => generated 52 bytes in 14 msecs (HTTP/1.1 500) 2 headers in 90 bytes (1 switches on core 6)
[2018-01-09 22:31:49,589] ERROR in app: Exception on /item/shirt [PUT]
Traceback (most recent call last):
  File "/var/www/html/items-rest/venv/lib/python3.4/site-packages/sqlalchemy/engine/base.py", line 1193, in _execute_context
    context)
  File "/var/www/html/items-rest/venv/lib/python3.4/site-packages/sqlalchemy/engine/default.py", line 507, in do_execute
    cursor.execute(statement, parameters)
psycopg2.IntegrityError: insert or update on table "items" violates foreign key constraint "items_store_id_fkey"
DETAIL:  Key (store_id)=(1) is not present in table "stores".


The above exception was the direct cause of the following exception:

Traceback (most recent call last):
  File "/var/www/html/items-rest/venv/lib/python3.4/site-packages/flask/app.py", line 1612, in full_dispatch_request
    rv = self.dispatch_request()
  File "/var/www/html/items-rest/venv/lib/python3.4/site-packages/flask/app.py", line 1598, in dispatch_request
    return self.view_functions[rule.endpoint](**req.view_args)
  File "/var/www/html/items-rest/venv/lib/python3.4/site-packages/flask_restful/__init__.py", line 480, in wrapper
    resp = resource(*args, **kwargs)
  File "/var/www/html/items-rest/venv/lib/python3.4/site-packages/flask/views.py", line 84, in view
    return self.dispatch_request(*args, **kwargs)
  File "/var/www/html/items-rest/venv/lib/python3.4/site-packages/flask_restful/__init__.py", line 595, in dispatch_request
    resp = meth(*args, **kwargs)
  File "/var/www/html/items-rest/resources/item.py", line 69, in put
    item.save_to_db()
  File "/var/www/html/items-rest/models/item.py", line 29, in save_to_db
    db.session.commit()
  File "/var/www/html/items-rest/venv/lib/python3.4/site-packages/sqlalchemy/orm/scoping.py", line 153, in do
    return getattr(self.registry(), name)(*args, **kwargs)
  File "/var/www/html/items-rest/venv/lib/python3.4/site-packages/sqlalchemy/orm/session.py", line 937, in commit
    self.transaction.commit()
  File "/var/www/html/items-rest/venv/lib/python3.4/site-packages/sqlalchemy/orm/session.py", line 461, in commit
    self._prepare_impl()
  File "/var/www/html/items-rest/venv/lib/python3.4/site-packages/sqlalchemy/orm/session.py", line 441, in _prepare_impl
    self.session.flush()
  File "/var/www/html/items-rest/venv/lib/python3.4/site-packages/sqlalchemy/orm/session.py", line 2237, in flush
    self._flush(objects)
  File "/var/www/html/items-rest/venv/lib/python3.4/site-packages/sqlalchemy/orm/session.py", line 2363, in _flush
    transaction.rollback(_capture_exception=True)
  File "/var/www/html/items-rest/venv/lib/python3.4/site-packages/sqlalchemy/util/langhelpers.py", line 66, in __exit__
    compat.reraise(exc_type, exc_value, exc_tb)
  File "/var/www/html/items-rest/venv/lib/python3.4/site-packages/sqlalchemy/util/compat.py", line 187, in reraise
    raise value
  File "/var/www/html/items-rest/venv/lib/python3.4/site-packages/sqlalchemy/orm/session.py", line 2327, in _flush
    flush_context.execute()
  File "/var/www/html/items-rest/venv/lib/python3.4/site-packages/sqlalchemy/orm/unitofwork.py", line 391, in execute
    rec.execute(self)
  File "/var/www/html/items-rest/venv/lib/python3.4/site-packages/sqlalchemy/orm/unitofwork.py", line 556, in execute
    uow
  File "/var/www/html/items-rest/venv/lib/python3.4/site-packages/sqlalchemy/orm/persistence.py", line 181, in save_obj
    mapper, table, insert)
  File "/var/www/html/items-rest/venv/lib/python3.4/site-packages/sqlalchemy/orm/persistence.py", line 866, in _emit_insert_statements
    execute(statement, params)
  File "/var/www/html/items-rest/venv/lib/python3.4/site-packages/sqlalchemy/engine/base.py", line 948, in execute
    return meth(self, multiparams, params)
  File "/var/www/html/items-rest/venv/lib/python3.4/site-packages/sqlalchemy/sql/elements.py", line 269, in _execute_on_connection
    return connection._execute_clauseelement(self, multiparams, params)
  File "/var/www/html/items-rest/venv/lib/python3.4/site-packages/sqlalchemy/engine/base.py", line 1060, in _execute_clauseelement
    compiled_sql, distilled_params
  File "/var/www/html/items-rest/venv/lib/python3.4/site-packages/sqlalchemy/engine/base.py", line 1200, in _execute_context
    context)
  File "/var/www/html/items-rest/venv/lib/python3.4/site-packages/sqlalchemy/engine/base.py", line 1413, in _handle_dbapi_exception
    exc_info
  File "/var/www/html/items-rest/venv/lib/python3.4/site-packages/sqlalchemy/util/compat.py", line 203, in raise_from_cause
    reraise(type(exception), exception, tb=exc_tb, cause=cause)
  File "/var/www/html/items-rest/venv/lib/python3.4/site-packages/sqlalchemy/util/compat.py", line 186, in reraise
    raise value.with_traceback(tb)
  File "/var/www/html/items-rest/venv/lib/python3.4/site-packages/sqlalchemy/engine/base.py", line 1193, in _execute_context
    context)
  File "/var/www/html/items-rest/venv/lib/python3.4/site-packages/sqlalchemy/engine/default.py", line 507, in do_execute
    cursor.execute(statement, parameters)
sqlalchemy.exc.IntegrityError: (psycopg2.IntegrityError) insert or update on table "items" violates foreign key constraint "items_store_id_fkey"
DETAIL:  Key (store_id)=(1) is not present in table "stores".
 [SQL: 'INSERT INTO items (name, price, store_id) VALUES (%(name)s, %(price)s, %(store_id)s) RETURNING items.id'] [parameters: {'price': 2.99, 'store_id': 1, 'name': 'shirt'}] (Background on this error at: http://sqlalche.me/e/gkpj)
[pid: 13298|app: 0|req: 4/7] 192.168.2.20 () {44 vars in 613 bytes} [Tue Jan  9 22:31:49 2018] PUT /item/shirt => generated 37 bytes in 16 msecs (HTTP/1.1 500) 2 headers in 90 bytes (1 switches on core 5)
[2018-01-09 22:34:02,730] ERROR in app: Exception on /item/shirt [PUT]
Traceback (most recent call last):
  File "/var/www/html/items-rest/venv/lib/python3.4/site-packages/sqlalchemy/engine/base.py", line 1193, in _execute_context
    context)
  File "/var/www/html/items-rest/venv/lib/python3.4/site-packages/sqlalchemy/engine/default.py", line 507, in do_execute
    cursor.execute(statement, parameters)
psycopg2.IntegrityError: insert or update on table "items" violates foreign key constraint "items_store_id_fkey"
DETAIL:  Key (store_id)=(2) is not present in table "stores".


The above exception was the direct cause of the following exception:

Traceback (most recent call last):
  File "/var/www/html/items-rest/venv/lib/python3.4/site-packages/flask/app.py", line 1612, in full_dispatch_request
    rv = self.dispatch_request()
  File "/var/www/html/items-rest/venv/lib/python3.4/site-packages/flask/app.py", line 1598, in dispatch_request
    return self.view_functions[rule.endpoint](**req.view_args)
  File "/var/www/html/items-rest/venv/lib/python3.4/site-packages/flask_restful/__init__.py", line 480, in wrapper
    resp = resource(*args, **kwargs)
  File "/var/www/html/items-rest/venv/lib/python3.4/site-packages/flask/views.py", line 84, in view
    return self.dispatch_request(*args, **kwargs)
  File "/var/www/html/items-rest/venv/lib/python3.4/site-packages/flask_restful/__init__.py", line 595, in dispatch_request
    resp = meth(*args, **kwargs)
  File "/var/www/html/items-rest/resources/item.py", line 69, in put
    item.save_to_db()
  File "/var/www/html/items-rest/models/item.py", line 29, in save_to_db
    db.session.commit()
  File "/var/www/html/items-rest/venv/lib/python3.4/site-packages/sqlalchemy/orm/scoping.py", line 153, in do
    return getattr(self.registry(), name)(*args, **kwargs)
  File "/var/www/html/items-rest/venv/lib/python3.4/site-packages/sqlalchemy/orm/session.py", line 937, in commit
    self.transaction.commit()
  File "/var/www/html/items-rest/venv/lib/python3.4/site-packages/sqlalchemy/orm/session.py", line 461, in commit
    self._prepare_impl()
  File "/var/www/html/items-rest/venv/lib/python3.4/site-packages/sqlalchemy/orm/session.py", line 441, in _prepare_impl
    self.session.flush()
  File "/var/www/html/items-rest/venv/lib/python3.4/site-packages/sqlalchemy/orm/session.py", line 2237, in flush
    self._flush(objects)
  File "/var/www/html/items-rest/venv/lib/python3.4/site-packages/sqlalchemy/orm/session.py", line 2363, in _flush
    transaction.rollback(_capture_exception=True)
  File "/var/www/html/items-rest/venv/lib/python3.4/site-packages/sqlalchemy/util/langhelpers.py", line 66, in __exit__
    compat.reraise(exc_type, exc_value, exc_tb)
  File "/var/www/html/items-rest/venv/lib/python3.4/site-packages/sqlalchemy/util/compat.py", line 187, in reraise
    raise value
  File "/var/www/html/items-rest/venv/lib/python3.4/site-packages/sqlalchemy/orm/session.py", line 2327, in _flush
    flush_context.execute()
  File "/var/www/html/items-rest/venv/lib/python3.4/site-packages/sqlalchemy/orm/unitofwork.py", line 391, in execute
    rec.execute(self)
  File "/var/www/html/items-rest/venv/lib/python3.4/site-packages/sqlalchemy/orm/unitofwork.py", line 556, in execute
    uow
  File "/var/www/html/items-rest/venv/lib/python3.4/site-packages/sqlalchemy/orm/persistence.py", line 181, in save_obj
    mapper, table, insert)
  File "/var/www/html/items-rest/venv/lib/python3.4/site-packages/sqlalchemy/orm/persistence.py", line 866, in _emit_insert_statements
    execute(statement, params)
  File "/var/www/html/items-rest/venv/lib/python3.4/site-packages/sqlalchemy/engine/base.py", line 948, in execute
    return meth(self, multiparams, params)
  File "/var/www/html/items-rest/venv/lib/python3.4/site-packages/sqlalchemy/sql/elements.py", line 269, in _execute_on_connection
    return connection._execute_clauseelement(self, multiparams, params)
  File "/var/www/html/items-rest/venv/lib/python3.4/site-packages/sqlalchemy/engine/base.py", line 1060, in _execute_clauseelement
    compiled_sql, distilled_params
  File "/var/www/html/items-rest/venv/lib/python3.4/site-packages/sqlalchemy/engine/base.py", line 1200, in _execute_context
    context)
  File "/var/www/html/items-rest/venv/lib/python3.4/site-packages/sqlalchemy/engine/base.py", line 1413, in _handle_dbapi_exception
    exc_info
  File "/var/www/html/items-rest/venv/lib/python3.4/site-packages/sqlalchemy/util/compat.py", line 203, in raise_from_cause
    reraise(type(exception), exception, tb=exc_tb, cause=cause)
  File "/var/www/html/items-rest/venv/lib/python3.4/site-packages/sqlalchemy/util/compat.py", line 186, in reraise
    raise value.with_traceback(tb)
  File "/var/www/html/items-rest/venv/lib/python3.4/site-packages/sqlalchemy/engine/base.py", line 1193, in _execute_context
    context)
  File "/var/www/html/items-rest/venv/lib/python3.4/site-packages/sqlalchemy/engine/default.py", line 507, in do_execute
    cursor.execute(statement, parameters)
sqlalchemy.exc.IntegrityError: (psycopg2.IntegrityError) insert or update on table "items" violates foreign key constraint "items_store_id_fkey"
DETAIL:  Key (store_id)=(2) is not present in table "stores".
 [SQL: 'INSERT INTO items (name, price, store_id) VALUES (%(name)s, %(price)s, %(store_id)s) RETURNING items.id'] [parameters: {'price': 2.99, 'store_id': 2, 'name': 'shirt'}] (Background on this error at: http://sqlalche.me/e/gkpj)
[pid: 13288|app: 0|req: 1/8] 192.168.2.20 () {44 vars in 613 bytes} [Tue Jan  9 22:34:02 2018] PUT /item/shirt => generated 37 bytes in 66 msecs (HTTP/1.1 500) 2 headers in 90 bytes (1 switches on core 0)
announcing my loyalty to the Emperor...
[2018-01-09 22:34:03,901] ERROR in app: Exception on /item/shirt [PUT]
Traceback (most recent call last):
  File "/var/www/html/items-rest/venv/lib/python3.4/site-packages/sqlalchemy/engine/base.py", line 1193, in _execute_context
    context)
  File "/var/www/html/items-rest/venv/lib/python3.4/site-packages/sqlalchemy/engine/default.py", line 507, in do_execute
    cursor.execute(statement, parameters)
psycopg2.IntegrityError: insert or update on table "items" violates foreign key constraint "items_store_id_fkey"
DETAIL:  Key (store_id)=(2) is not present in table "stores".


The above exception was the direct cause of the following exception:

Traceback (most recent call last):
  File "/var/www/html/items-rest/venv/lib/python3.4/site-packages/flask/app.py", line 1612, in full_dispatch_request
    rv = self.dispatch_request()
  File "/var/www/html/items-rest/venv/lib/python3.4/site-packages/flask/app.py", line 1598, in dispatch_request
    return self.view_functions[rule.endpoint](**req.view_args)
  File "/var/www/html/items-rest/venv/lib/python3.4/site-packages/flask_restful/__init__.py", line 480, in wrapper
    resp = resource(*args, **kwargs)
  File "/var/www/html/items-rest/venv/lib/python3.4/site-packages/flask/views.py", line 84, in view
    return self.dispatch_request(*args, **kwargs)
  File "/var/www/html/items-rest/venv/lib/python3.4/site-packages/flask_restful/__init__.py", line 595, in dispatch_request
    resp = meth(*args, **kwargs)
  File "/var/www/html/items-rest/resources/item.py", line 69, in put
    item.save_to_db()
  File "/var/www/html/items-rest/models/item.py", line 29, in save_to_db
    db.session.commit()
  File "/var/www/html/items-rest/venv/lib/python3.4/site-packages/sqlalchemy/orm/scoping.py", line 153, in do
    return getattr(self.registry(), name)(*args, **kwargs)
  File "/var/www/html/items-rest/venv/lib/python3.4/site-packages/sqlalchemy/orm/session.py", line 937, in commit
    self.transaction.commit()
  File "/var/www/html/items-rest/venv/lib/python3.4/site-packages/sqlalchemy/orm/session.py", line 461, in commit
    self._prepare_impl()
  File "/var/www/html/items-rest/venv/lib/python3.4/site-packages/sqlalchemy/orm/session.py", line 441, in _prepare_impl
    self.session.flush()
  File "/var/www/html/items-rest/venv/lib/python3.4/site-packages/sqlalchemy/orm/session.py", line 2237, in flush
    self._flush(objects)
  File "/var/www/html/items-rest/venv/lib/python3.4/site-packages/sqlalchemy/orm/session.py", line 2363, in _flush
    transaction.rollback(_capture_exception=True)
  File "/var/www/html/items-rest/venv/lib/python3.4/site-packages/sqlalchemy/util/langhelpers.py", line 66, in __exit__
    compat.reraise(exc_type, exc_value, exc_tb)
  File "/var/www/html/items-rest/venv/lib/python3.4/site-packages/sqlalchemy/util/compat.py", line 187, in reraise
    raise value
  File "/var/www/html/items-rest/venv/lib/python3.4/site-packages/sqlalchemy/orm/session.py", line 2327, in _flush
    flush_context.execute()
  File "/var/www/html/items-rest/venv/lib/python3.4/site-packages/sqlalchemy/orm/unitofwork.py", line 391, in execute
    rec.execute(self)
  File "/var/www/html/items-rest/venv/lib/python3.4/site-packages/sqlalchemy/orm/unitofwork.py", line 556, in execute
    uow
  File "/var/www/html/items-rest/venv/lib/python3.4/site-packages/sqlalchemy/orm/persistence.py", line 181, in save_obj
    mapper, table, insert)
  File "/var/www/html/items-rest/venv/lib/python3.4/site-packages/sqlalchemy/orm/persistence.py", line 866, in _emit_insert_statements
    execute(statement, params)
  File "/var/www/html/items-rest/venv/lib/python3.4/site-packages/sqlalchemy/engine/base.py", line 948, in execute
    return meth(self, multiparams, params)
  File "/var/www/html/items-rest/venv/lib/python3.4/site-packages/sqlalchemy/sql/elements.py", line 269, in _execute_on_connection
    return connection._execute_clauseelement(self, multiparams, params)
  File "/var/www/html/items-rest/venv/lib/python3.4/site-packages/sqlalchemy/engine/base.py", line 1060, in _execute_clauseelement
    compiled_sql, distilled_params
  File "/var/www/html/items-rest/venv/lib/python3.4/site-packages/sqlalchemy/engine/base.py", line 1200, in _execute_context
    context)
  File "/var/www/html/items-rest/venv/lib/python3.4/site-packages/sqlalchemy/engine/base.py", line 1413, in _handle_dbapi_exception
    exc_info
  File "/var/www/html/items-rest/venv/lib/python3.4/site-packages/sqlalchemy/util/compat.py", line 203, in raise_from_cause
    reraise(type(exception), exception, tb=exc_tb, cause=cause)
  File "/var/www/html/items-rest/venv/lib/python3.4/site-packages/sqlalchemy/util/compat.py", line 186, in reraise
    raise value.with_traceback(tb)
  File "/var/www/html/items-rest/venv/lib/python3.4/site-packages/sqlalchemy/engine/base.py", line 1193, in _execute_context
    context)
  File "/var/www/html/items-rest/venv/lib/python3.4/site-packages/sqlalchemy/engine/default.py", line 507, in do_execute
    cursor.execute(statement, parameters)
sqlalchemy.exc.IntegrityError: (psycopg2.IntegrityError) insert or update on table "items" violates foreign key constraint "items_store_id_fkey"
DETAIL:  Key (store_id)=(2) is not present in table "stores".
 [SQL: 'INSERT INTO items (name, price, store_id) VALUES (%(name)s, %(price)s, %(store_id)s) RETURNING items.id'] [parameters: {'price': 2.99, 'store_id': 2, 'name': 'shirt'}] (Background on this error at: http://sqlalche.me/e/gkpj)
[pid: 13298|app: 0|req: 5/9] 192.168.2.20 () {44 vars in 613 bytes} [Tue Jan  9 22:34:03 2018] PUT /item/shirt => generated 37 bytes in 11 msecs (HTTP/1.1 500) 2 headers in 90 bytes (1 switches on core 2)
[2018-01-09 22:34:04,130] ERROR in app: Exception on /item/shirt [PUT]
Traceback (most recent call last):
  File "/var/www/html/items-rest/venv/lib/python3.4/site-packages/sqlalchemy/engine/base.py", line 1193, in _execute_context
    context)
  File "/var/www/html/items-rest/venv/lib/python3.4/site-packages/sqlalchemy/engine/default.py", line 507, in do_execute
    cursor.execute(statement, parameters)
psycopg2.IntegrityError: insert or update on table "items" violates foreign key constraint "items_store_id_fkey"
DETAIL:  Key (store_id)=(2) is not present in table "stores".


The above exception was the direct cause of the following exception:

Traceback (most recent call last):
  File "/var/www/html/items-rest/venv/lib/python3.4/site-packages/flask/app.py", line 1612, in full_dispatch_request
    rv = self.dispatch_request()
  File "/var/www/html/items-rest/venv/lib/python3.4/site-packages/flask/app.py", line 1598, in dispatch_request
    return self.view_functions[rule.endpoint](**req.view_args)
  File "/var/www/html/items-rest/venv/lib/python3.4/site-packages/flask_restful/__init__.py", line 480, in wrapper
    resp = resource(*args, **kwargs)
  File "/var/www/html/items-rest/venv/lib/python3.4/site-packages/flask/views.py", line 84, in view
    return self.dispatch_request(*args, **kwargs)
  File "/var/www/html/items-rest/venv/lib/python3.4/site-packages/flask_restful/__init__.py", line 595, in dispatch_request
    resp = meth(*args, **kwargs)
  File "/var/www/html/items-rest/resources/item.py", line 69, in put
    item.save_to_db()
  File "/var/www/html/items-rest/models/item.py", line 29, in save_to_db
    db.session.commit()
  File "/var/www/html/items-rest/venv/lib/python3.4/site-packages/sqlalchemy/orm/scoping.py", line 153, in do
    return getattr(self.registry(), name)(*args, **kwargs)
  File "/var/www/html/items-rest/venv/lib/python3.4/site-packages/sqlalchemy/orm/session.py", line 937, in commit
    self.transaction.commit()
  File "/var/www/html/items-rest/venv/lib/python3.4/site-packages/sqlalchemy/orm/session.py", line 461, in commit
    self._prepare_impl()
  File "/var/www/html/items-rest/venv/lib/python3.4/site-packages/sqlalchemy/orm/session.py", line 441, in _prepare_impl
    self.session.flush()
  File "/var/www/html/items-rest/venv/lib/python3.4/site-packages/sqlalchemy/orm/session.py", line 2237, in flush
    self._flush(objects)
  File "/var/www/html/items-rest/venv/lib/python3.4/site-packages/sqlalchemy/orm/session.py", line 2363, in _flush
    transaction.rollback(_capture_exception=True)
  File "/var/www/html/items-rest/venv/lib/python3.4/site-packages/sqlalchemy/util/langhelpers.py", line 66, in __exit__
    compat.reraise(exc_type, exc_value, exc_tb)
  File "/var/www/html/items-rest/venv/lib/python3.4/site-packages/sqlalchemy/util/compat.py", line 187, in reraise
    raise value
  File "/var/www/html/items-rest/venv/lib/python3.4/site-packages/sqlalchemy/orm/session.py", line 2327, in _flush
    flush_context.execute()
  File "/var/www/html/items-rest/venv/lib/python3.4/site-packages/sqlalchemy/orm/unitofwork.py", line 391, in execute
    rec.execute(self)
  File "/var/www/html/items-rest/venv/lib/python3.4/site-packages/sqlalchemy/orm/unitofwork.py", line 556, in execute
    uow
  File "/var/www/html/items-rest/venv/lib/python3.4/site-packages/sqlalchemy/orm/persistence.py", line 181, in save_obj
    mapper, table, insert)
  File "/var/www/html/items-rest/venv/lib/python3.4/site-packages/sqlalchemy/orm/persistence.py", line 866, in _emit_insert_statements
    execute(statement, params)
  File "/var/www/html/items-rest/venv/lib/python3.4/site-packages/sqlalchemy/engine/base.py", line 948, in execute
    return meth(self, multiparams, params)
  File "/var/www/html/items-rest/venv/lib/python3.4/site-packages/sqlalchemy/sql/elements.py", line 269, in _execute_on_connection
    return connection._execute_clauseelement(self, multiparams, params)
  File "/var/www/html/items-rest/venv/lib/python3.4/site-packages/sqlalchemy/engine/base.py", line 1060, in _execute_clauseelement
    compiled_sql, distilled_params
  File "/var/www/html/items-rest/venv/lib/python3.4/site-packages/sqlalchemy/engine/base.py", line 1200, in _execute_context
    context)
  File "/var/www/html/items-rest/venv/lib/python3.4/site-packages/sqlalchemy/engine/base.py", line 1413, in _handle_dbapi_exception
    exc_info
  File "/var/www/html/items-rest/venv/lib/python3.4/site-packages/sqlalchemy/util/compat.py", line 203, in raise_from_cause
    reraise(type(exception), exception, tb=exc_tb, cause=cause)
  File "/var/www/html/items-rest/venv/lib/python3.4/site-packages/sqlalchemy/util/compat.py", line 186, in reraise
    raise value.with_traceback(tb)
  File "/var/www/html/items-rest/venv/lib/python3.4/site-packages/sqlalchemy/engine/base.py", line 1193, in _execute_context
    context)
  File "/var/www/html/items-rest/venv/lib/python3.4/site-packages/sqlalchemy/engine/default.py", line 507, in do_execute
    cursor.execute(statement, parameters)
sqlalchemy.exc.IntegrityError: (psycopg2.IntegrityError) insert or update on table "items" violates foreign key constraint "items_store_id_fkey"
DETAIL:  Key (store_id)=(2) is not present in table "stores".
 [SQL: 'INSERT INTO items (name, price, store_id) VALUES (%(name)s, %(price)s, %(store_id)s) RETURNING items.id'] [parameters: {'price': 2.99, 'store_id': 2, 'name': 'shirt'}] (Background on this error at: http://sqlalche.me/e/gkpj)
[pid: 13309|app: 0|req: 3/10] 192.168.2.20 () {44 vars in 613 bytes} [Tue Jan  9 22:34:04 2018] PUT /item/shirt => generated 37 bytes in 14 msecs (HTTP/1.1 500) 2 headers in 90 bytes (1 switches on core 5)
[2018-01-09 22:34:44,460] ERROR in app: Exception on /item/shirt [PUT]
Traceback (most recent call last):
  File "/var/www/html/items-rest/venv/lib/python3.4/site-packages/sqlalchemy/engine/base.py", line 1193, in _execute_context
    context)
  File "/var/www/html/items-rest/venv/lib/python3.4/site-packages/sqlalchemy/engine/default.py", line 507, in do_execute
    cursor.execute(statement, parameters)
psycopg2.IntegrityError: insert or update on table "items" violates foreign key constraint "items_store_id_fkey"
DETAIL:  Key (store_id)=(2) is not present in table "stores".


The above exception was the direct cause of the following exception:

Traceback (most recent call last):
  File "/var/www/html/items-rest/venv/lib/python3.4/site-packages/flask/app.py", line 1612, in full_dispatch_request
    rv = self.dispatch_request()
  File "/var/www/html/items-rest/venv/lib/python3.4/site-packages/flask/app.py", line 1598, in dispatch_request
    return self.view_functions[rule.endpoint](**req.view_args)
  File "/var/www/html/items-rest/venv/lib/python3.4/site-packages/flask_restful/__init__.py", line 480, in wrapper
    resp = resource(*args, **kwargs)
  File "/var/www/html/items-rest/venv/lib/python3.4/site-packages/flask/views.py", line 84, in view
    return self.dispatch_request(*args, **kwargs)
  File "/var/www/html/items-rest/venv/lib/python3.4/site-packages/flask_restful/__init__.py", line 595, in dispatch_request
    resp = meth(*args, **kwargs)
  File "/var/www/html/items-rest/resources/item.py", line 69, in put
    item.save_to_db()
  File "/var/www/html/items-rest/models/item.py", line 29, in save_to_db
    db.session.commit()
  File "/var/www/html/items-rest/venv/lib/python3.4/site-packages/sqlalchemy/orm/scoping.py", line 153, in do
    return getattr(self.registry(), name)(*args, **kwargs)
  File "/var/www/html/items-rest/venv/lib/python3.4/site-packages/sqlalchemy/orm/session.py", line 937, in commit
    self.transaction.commit()
  File "/var/www/html/items-rest/venv/lib/python3.4/site-packages/sqlalchemy/orm/session.py", line 461, in commit
    self._prepare_impl()
  File "/var/www/html/items-rest/venv/lib/python3.4/site-packages/sqlalchemy/orm/session.py", line 441, in _prepare_impl
    self.session.flush()
  File "/var/www/html/items-rest/venv/lib/python3.4/site-packages/sqlalchemy/orm/session.py", line 2237, in flush
    self._flush(objects)
  File "/var/www/html/items-rest/venv/lib/python3.4/site-packages/sqlalchemy/orm/session.py", line 2363, in _flush
    transaction.rollback(_capture_exception=True)
  File "/var/www/html/items-rest/venv/lib/python3.4/site-packages/sqlalchemy/util/langhelpers.py", line 66, in __exit__
    compat.reraise(exc_type, exc_value, exc_tb)
  File "/var/www/html/items-rest/venv/lib/python3.4/site-packages/sqlalchemy/util/compat.py", line 187, in reraise
    raise value
  File "/var/www/html/items-rest/venv/lib/python3.4/site-packages/sqlalchemy/orm/session.py", line 2327, in _flush
    flush_context.execute()
  File "/var/www/html/items-rest/venv/lib/python3.4/site-packages/sqlalchemy/orm/unitofwork.py", line 391, in execute
    rec.execute(self)
  File "/var/www/html/items-rest/venv/lib/python3.4/site-packages/sqlalchemy/orm/unitofwork.py", line 556, in execute
    uow
  File "/var/www/html/items-rest/venv/lib/python3.4/site-packages/sqlalchemy/orm/persistence.py", line 181, in save_obj
    mapper, table, insert)
  File "/var/www/html/items-rest/venv/lib/python3.4/site-packages/sqlalchemy/orm/persistence.py", line 866, in _emit_insert_statements
    execute(statement, params)
  File "/var/www/html/items-rest/venv/lib/python3.4/site-packages/sqlalchemy/engine/base.py", line 948, in execute
    return meth(self, multiparams, params)
  File "/var/www/html/items-rest/venv/lib/python3.4/site-packages/sqlalchemy/sql/elements.py", line 269, in _execute_on_connection
    return connection._execute_clauseelement(self, multiparams, params)
  File "/var/www/html/items-rest/venv/lib/python3.4/site-packages/sqlalchemy/engine/base.py", line 1060, in _execute_clauseelement
    compiled_sql, distilled_params
  File "/var/www/html/items-rest/venv/lib/python3.4/site-packages/sqlalchemy/engine/base.py", line 1200, in _execute_context
    context)
  File "/var/www/html/items-rest/venv/lib/python3.4/site-packages/sqlalchemy/engine/base.py", line 1413, in _handle_dbapi_exception
    exc_info
  File "/var/www/html/items-rest/venv/lib/python3.4/site-packages/sqlalchemy/util/compat.py", line 203, in raise_from_cause
    reraise(type(exception), exception, tb=exc_tb, cause=cause)
  File "/var/www/html/items-rest/venv/lib/python3.4/site-packages/sqlalchemy/util/compat.py", line 186, in reraise
    raise value.with_traceback(tb)
  File "/var/www/html/items-rest/venv/lib/python3.4/site-packages/sqlalchemy/engine/base.py", line 1193, in _execute_context
    context)
  File "/var/www/html/items-rest/venv/lib/python3.4/site-packages/sqlalchemy/engine/default.py", line 507, in do_execute
    cursor.execute(statement, parameters)
sqlalchemy.exc.IntegrityError: (psycopg2.IntegrityError) insert or update on table "items" violates foreign key constraint "items_store_id_fkey"
DETAIL:  Key (store_id)=(2) is not present in table "stores".
 [SQL: 'INSERT INTO items (name, price, store_id) VALUES (%(name)s, %(price)s, %(store_id)s) RETURNING items.id'] [parameters: {'price': 2.99, 'store_id': 2, 'name': 'shirt'}] (Background on this error at: http://sqlalche.me/e/gkpj)
[pid: 13298|app: 0|req: 6/11] 192.168.2.20 () {44 vars in 613 bytes} [Tue Jan  9 22:34:44 2018] PUT /item/shirt => generated 37 bytes in 15 msecs (HTTP/1.1 500) 2 headers in 90 bytes (1 switches on core 1)
[pid: 13289|app: 0|req: 1/12] 192.168.2.20 () {44 vars in 606 bytes} [Tue Jan  9 22:35:21 2018] POST /store/2 => generated 27 bytes in 108 msecs (HTTP/1.1 201) 2 headers in 76 bytes (1 switches on core 0)
announcing my loyalty to the Emperor...
[pid: 13298|app: 0|req: 7/13] 192.168.2.20 () {44 vars in 614 bytes} [Tue Jan  9 22:35:45 2018] POST /item/shirt => generated 52 bytes in 15 msecs (HTTP/1.1 500) 2 headers in 90 bytes (1 switches on core 4)
[pid: 13309|app: 0|req: 4/14] 192.168.2.20 () {40 vars in 525 bytes} [Tue Jan  9 22:35:55 2018] GET /stores => generated 41 bytes in 10 msecs (HTTP/1.1 200) 2 headers in 71 bytes (1 switches on core 7)
[pid: 13299|app: 0|req: 1/15] 192.168.2.20 () {44 vars in 612 bytes} [Tue Jan  9 22:36:17 2018] POST /item/wood => generated 52 bytes in 66 msecs (HTTP/1.1 500) 2 headers in 90 bytes (1 switches on core 0)
announcing my loyalty to the Emperor...
[pid: 13309|app: 0|req: 5/16] 192.168.2.20 () {40 vars in 525 bytes} [Tue Jan  9 22:38:46 2018] GET /stores => generated 41 bytes in 9 msecs (HTTP/1.1 200) 2 headers in 71 bytes (1 switches on core 1)
[pid: 13289|app: 0|req: 2/17] 192.168.2.20 () {44 vars in 612 bytes} [Tue Jan  9 22:39:08 2018] POST /store/test => generated 30 bytes in 36 msecs (HTTP/1.1 201) 2 headers in 76 bytes (1 switches on core 2)
[pid: 13309|app: 0|req: 6/18] 192.168.2.20 () {44 vars in 610 bytes} [Tue Jan  9 22:40:09 2018] POST /item/car => generated 52 bytes in 8 msecs (HTTP/1.1 500) 2 headers in 90 bytes (1 switches on core 2)
SIGINT/SIGQUIT received...killing workers...
Tue Jan  9 22:42:24 2018 - received message 0 from emperor
worker 1 buried after 1 seconds
worker 2 buried after 1 seconds
worker 3 buried after 1 seconds
worker 4 buried after 1 seconds
worker 5 buried after 1 seconds
worker 6 buried after 1 seconds
worker 7 buried after 1 seconds
worker 8 buried after 1 seconds
goodbye to uWSGI.
*** Starting uWSGI 2.0.15 (64bit) on [Tue Jan  9 22:42:28 2018] ***
compiled with version: 4.8.5 20150623 (Red Hat 4.8.5-16) on 09 January 2018 21:39:16
os: Linux-3.10.0-229.el7.x86_64 #1 SMP Fri Mar 6 11:36:42 UTC 2015
nodename: rest-app01
machine: x86_64
clock source: unix
detected number of CPU cores: 2
current working directory: /
detected binary path: /var/www/html/items-rest/venv/bin/uwsgi
!!! no internal routing support, rebuild with pcre support !!!
your processes number limit is 7285
your memory page size is 4096 bytes
 *** WARNING: you have enabled harakiri without post buffering. Slow upload could be rejected on post-unbuffered webservers *** 
detected max file descriptor number: 1024
lock engine: pthread robust mutexes
thunder lock: disabled (you can enable it with --thunder-lock)
uwsgi socket 0 bound to UNIX address /var/www/html/items-rest/socket.sock fd 3
Python version: 3.4.5 (default, Dec 11 2017, 14:22:24)  [GCC 4.8.5 20150623 (Red Hat 4.8.5-16)]
Set PythonHome to /var/www/html/items-rest/venv
Python main interpreter initialized at 0x1f60690
python threads support enabled
your server socket listen backlog is limited to 100 connections
your mercy for graceful operations on workers is 60 seconds
mapped 1303488 bytes (1272 KB) for 64 cores
*** Operational MODE: preforking+threaded ***
added /var/www/html/items-rest/ to pythonpath.
WSGI app 0 (mountpoint='') ready in 0 seconds on interpreter 0x1f60690 pid: 13551 (default app)
*** uWSGI is running in multiple interpreter mode ***
spawned uWSGI master process (pid: 13551)
spawned uWSGI worker 1 (pid: 13553, cores: 8)
spawned uWSGI worker 2 (pid: 13554, cores: 8)
spawned uWSGI worker 3 (pid: 13555, cores: 8)
spawned uWSGI worker 4 (pid: 13563, cores: 8)
spawned uWSGI worker 5 (pid: 13564, cores: 8)
spawned uWSGI worker 6 (pid: 13572, cores: 8)
spawned uWSGI worker 7 (pid: 13573, cores: 8)
spawned uWSGI worker 8 (pid: 13574, cores: 8)
*** Starting uWSGI 2.0.15 (64bit) on [Tue Jan  9 22:44:12 2018] ***
compiled with version: 4.8.5 20150623 (Red Hat 4.8.5-16) on 09 January 2018 21:39:16
os: Linux-3.10.0-229.el7.x86_64 #1 SMP Fri Mar 6 11:36:42 UTC 2015
nodename: rest-app01
machine: x86_64
clock source: unix
detected number of CPU cores: 2
current working directory: /
detected binary path: /var/www/html/items-rest/venv/bin/uwsgi
!!! no internal routing support, rebuild with pcre support !!!
your processes number limit is 7285
your memory page size is 4096 bytes
 *** WARNING: you have enabled harakiri without post buffering. Slow upload could be rejected on post-unbuffered webservers *** 
detected max file descriptor number: 1024
lock engine: pthread robust mutexes
thunder lock: disabled (you can enable it with --thunder-lock)
uwsgi socket 0 bound to UNIX address /var/www/html/items-rest/socket.sock fd 3
Python version: 3.4.5 (default, Dec 11 2017, 14:22:24)  [GCC 4.8.5 20150623 (Red Hat 4.8.5-16)]
Set PythonHome to /var/www/html/items-rest/venv
Python main interpreter initialized at 0x1a56690
python threads support enabled
your server socket listen backlog is limited to 100 connections
your mercy for graceful operations on workers is 60 seconds
mapped 1303488 bytes (1272 KB) for 64 cores
*** Operational MODE: preforking+threaded ***
added /var/www/html/items-rest/ to pythonpath.
WSGI app 0 (mountpoint='') ready in 0 seconds on interpreter 0x1a56690 pid: 13626 (default app)
*** uWSGI is running in multiple interpreter mode ***
spawned uWSGI master process (pid: 13626)
spawned uWSGI worker 1 (pid: 13628, cores: 8)
spawned uWSGI worker 2 (pid: 13629, cores: 8)
spawned uWSGI worker 3 (pid: 13630, cores: 8)
spawned uWSGI worker 4 (pid: 13633, cores: 8)
spawned uWSGI worker 5 (pid: 13639, cores: 8)
spawned uWSGI worker 6 (pid: 13640, cores: 8)
spawned uWSGI worker 7 (pid: 13648, cores: 8)
spawned uWSGI worker 8 (pid: 13649, cores: 8)
[pid: 13649|app: 0|req: 1/1] 192.168.2.20 () {44 vars in 610 bytes} [Tue Jan  9 22:44:43 2018] POST /item/car => generated 52 bytes in 52 msecs (HTTP/1.1 500) 2 headers in 90 bytes (1 switches on core 0)
announcing my loyalty to the Emperor...
[pid: 13649|app: 0|req: 2/2] 192.168.2.20 () {44 vars in 610 bytes} [Tue Jan  9 22:44:45 2018] POST /item/car => generated 52 bytes in 8 msecs (HTTP/1.1 500) 2 headers in 90 bytes (2 switches on core 4)
[pid: 13649|app: 0|req: 3/3] 192.168.2.20 () {44 vars in 610 bytes} [Tue Jan  9 22:46:10 2018] POST /register => generated 42 bytes in 21 msecs (HTTP/1.1 201) 2 headers in 76 bytes (1 switches on core 6)
[pid: 13649|app: 0|req: 4/4] 192.168.2.20 () {44 vars in 612 bytes} [Tue Jan  9 22:46:27 2018] POST /store/test => generated 56 bytes in 7 msecs (HTTP/1.1 400) 2 headers in 80 bytes (1 switches on core 1)
[pid: 13649|app: 0|req: 5/5] 192.168.2.20 () {40 vars in 525 bytes} [Tue Jan  9 22:46:35 2018] GET /stores => generated 72 bytes in 10 msecs (HTTP/1.1 200) 2 headers in 71 bytes (1 switches on core 2)
[pid: 13649|app: 0|req: 6/6] 192.168.2.20 () {44 vars in 612 bytes} [Tue Jan  9 22:46:54 2018] POST /store/toys => generated 30 bytes in 49 msecs (HTTP/1.1 201) 2 headers in 76 bytes (1 switches on core 3)
[pid: 13628|app: 0|req: 1/7] 192.168.2.20 () {40 vars in 525 bytes} [Tue Jan  9 22:47:07 2018] GET /stores => generated 103 bytes in 75 msecs (HTTP/1.1 200) 2 headers in 72 bytes (1 switches on core 0)
announcing my loyalty to the Emperor...
[pid: 13649|app: 0|req: 7/8] 192.168.2.20 () {44 vars in 616 bytes} [Tue Jan  9 22:47:35 2018] POST /item/skates => generated 37 bytes in 52 msecs (HTTP/1.1 201) 2 headers in 76 bytes (1 switches on core 5)
[pid: 13649|app: 0|req: 8/9] 192.168.2.20 () {40 vars in 523 bytes} [Tue Jan  9 22:47:59 2018] GET /items => generated 50 bytes in 6 msecs (HTTP/1.1 200) 2 headers in 71 bytes (1 switches on core 7)
SIGINT/SIGQUIT received...killing workers...
Sun Feb 11 10:32:40 2018 - received message 0 from emperor
worker 4 buried after 0 seconds
worker 1 buried after 1 seconds
worker 2 buried after 1 seconds
worker 3 buried after 1 seconds
worker 5 buried after 1 seconds
worker 6 buried after 1 seconds
worker 7 buried after 1 seconds
worker 8 buried after 1 seconds
goodbye to uWSGI.
*** Starting uWSGI 2.0.15 (64bit) on [Sun Feb 11 10:32:43 2018] ***
compiled with version: 4.8.5 20150623 (Red Hat 4.8.5-16) on 09 January 2018 21:39:16
os: Linux-3.10.0-229.el7.x86_64 #1 SMP Fri Mar 6 11:36:42 UTC 2015
nodename: rest-app01
machine: x86_64
clock source: unix
detected number of CPU cores: 2
current working directory: /
detected binary path: /var/www/html/items-rest/venv/bin/uwsgi
!!! no internal routing support, rebuild with pcre support !!!
your processes number limit is 7285
your memory page size is 4096 bytes
 *** WARNING: you have enabled harakiri without post buffering. Slow upload could be rejected on post-unbuffered webservers *** 
detected max file descriptor number: 1024
lock engine: pthread robust mutexes
thunder lock: disabled (you can enable it with --thunder-lock)
uwsgi socket 0 bound to UNIX address /var/www/html/items-rest/socket.sock fd 3
Python version: 3.4.5 (default, Dec 11 2017, 14:22:24)  [GCC 4.8.5 20150623 (Red Hat 4.8.5-16)]
Set PythonHome to /var/www/html/items-rest/venv
Python main interpreter initialized at 0x1060690
python threads support enabled
your server socket listen backlog is limited to 100 connections
your mercy for graceful operations on workers is 60 seconds
mapped 1303488 bytes (1272 KB) for 64 cores
*** Operational MODE: preforking+threaded ***
added /var/www/html/items-rest/ to pythonpath.
WSGI app 0 (mountpoint='') ready in 1 seconds on interpreter 0x1060690 pid: 5074 (default app)
*** uWSGI is running in multiple interpreter mode ***
spawned uWSGI master process (pid: 5074)
spawned uWSGI worker 1 (pid: 5076, cores: 8)
spawned uWSGI worker 2 (pid: 5077, cores: 8)
spawned uWSGI worker 3 (pid: 5085, cores: 8)
spawned uWSGI worker 4 (pid: 5086, cores: 8)
spawned uWSGI worker 5 (pid: 5087, cores: 8)
spawned uWSGI worker 6 (pid: 5095, cores: 8)
spawned uWSGI worker 7 (pid: 5096, cores: 8)
spawned uWSGI worker 8 (pid: 5097, cores: 8)
*** Starting uWSGI 2.0.15 (64bit) on [Sun Mar 25 22:49:42 2018] ***
compiled with version: 4.8.5 20150623 (Red Hat 4.8.5-16) on 09 January 2018 21:39:16
os: Linux-3.10.0-693.21.1.el7.x86_64 #1 SMP Wed Mar 7 19:03:37 UTC 2018
nodename: rest-app01
machine: x86_64
clock source: unix
detected number of CPU cores: 2
current working directory: /
detected binary path: /var/www/html/items-rest/venv/bin/uwsgi
!!! no internal routing support, rebuild with pcre support !!!
your processes number limit is 7268
your memory page size is 4096 bytes
 *** WARNING: you have enabled harakiri without post buffering. Slow upload could be rejected on post-unbuffered webservers *** 
detected max file descriptor number: 1024
lock engine: pthread robust mutexes
thunder lock: disabled (you can enable it with --thunder-lock)
uwsgi socket 0 bound to UNIX address /var/www/html/items-rest/socket.sock fd 3
Python version: 3.4.5 (default, Dec 11 2017, 14:22:24)  [GCC 4.8.5 20150623 (Red Hat 4.8.5-16)]
Set PythonHome to /var/www/html/items-rest/venv
Python main interpreter initialized at 0x1606690
python threads support enabled
your server socket listen backlog is limited to 100 connections
your mercy for graceful operations on workers is 60 seconds
mapped 1303488 bytes (1272 KB) for 64 cores
*** Operational MODE: preforking+threaded ***
added /var/www/html/items-rest/ to pythonpath.
WSGI app 0 (mountpoint='') ready in 1 seconds on interpreter 0x1606690 pid: 23694 (default app)
*** uWSGI is running in multiple interpreter mode ***
spawned uWSGI master process (pid: 23694)
spawned uWSGI worker 1 (pid: 23696, cores: 8)
spawned uWSGI worker 2 (pid: 23697, cores: 8)
spawned uWSGI worker 3 (pid: 23698, cores: 8)
spawned uWSGI worker 4 (pid: 23706, cores: 8)
spawned uWSGI worker 5 (pid: 23717, cores: 8)
spawned uWSGI worker 6 (pid: 23719, cores: 8)
spawned uWSGI worker 7 (pid: 23744, cores: 8)
spawned uWSGI worker 8 (pid: 23745, cores: 8)
[pid: 23696|app: 0|req: 1/1] 192.168.2.242 () {40 vars in 647 bytes} [Sun Mar 25 22:49:56 2018] GET / => generated 233 bytes in 2160 msecs (HTTP/1.1 404) 2 headers in 72 bytes (1 switches on core 0)
announcing my loyalty to the Emperor...
SIGINT/SIGQUIT received...killing workers...
Sun Mar 25 22:51:46 2018 - received message 0 from emperor
worker 1 buried after 1 seconds
worker 2 buried after 1 seconds
worker 3 buried after 1 seconds
worker 4 buried after 1 seconds
worker 5 buried after 1 seconds
worker 6 buried after 1 seconds
worker 7 buried after 1 seconds
worker 8 buried after 1 seconds
goodbye to uWSGI.
*** Starting uWSGI 2.0.15 (64bit) on [Sun Mar 25 22:51:49 2018] ***
compiled with version: 4.8.5 20150623 (Red Hat 4.8.5-16) on 09 January 2018 21:39:16
os: Linux-3.10.0-693.21.1.el7.x86_64 #1 SMP Wed Mar 7 19:03:37 UTC 2018
nodename: rest-app01
machine: x86_64
clock source: unix
detected number of CPU cores: 2
current working directory: /
detected binary path: /var/www/html/items-rest/venv/bin/uwsgi
!!! no internal routing support, rebuild with pcre support !!!
your processes number limit is 7268
your memory page size is 4096 bytes
 *** WARNING: you have enabled harakiri without post buffering. Slow upload could be rejected on post-unbuffered webservers *** 
detected max file descriptor number: 1024
lock engine: pthread robust mutexes
thunder lock: disabled (you can enable it with --thunder-lock)
uwsgi socket 0 bound to UNIX address /var/www/html/items-rest/socket.sock fd 3
Python version: 3.4.5 (default, Dec 11 2017, 14:22:24)  [GCC 4.8.5 20150623 (Red Hat 4.8.5-16)]
Set PythonHome to /var/www/html/items-rest/venv
Python main interpreter initialized at 0x2521690
python threads support enabled
your server socket listen backlog is limited to 100 connections
your mercy for graceful operations on workers is 60 seconds
mapped 1303488 bytes (1272 KB) for 64 cores
*** Operational MODE: preforking+threaded ***
added /var/www/html/items-rest/ to pythonpath.
WSGI app 0 (mountpoint='') ready in 0 seconds on interpreter 0x2521690 pid: 23776 (default app)
*** uWSGI is running in multiple interpreter mode ***
spawned uWSGI master process (pid: 23776)
spawned uWSGI worker 1 (pid: 23778, cores: 8)
spawned uWSGI worker 2 (pid: 23779, cores: 8)
spawned uWSGI worker 3 (pid: 23787, cores: 8)
spawned uWSGI worker 4 (pid: 23788, cores: 8)
spawned uWSGI worker 5 (pid: 23789, cores: 8)
spawned uWSGI worker 6 (pid: 23797, cores: 8)
spawned uWSGI worker 7 (pid: 23798, cores: 8)
spawned uWSGI worker 8 (pid: 23806, cores: 8)
